test_anagram (__main__.TestExercice) ... FAIL
test_doubles (__main__.TestExercice) ... FAIL
test_grades (__main__.TestExercice) ... FAIL
test_histogram (__main__.TestExercice) ... FAIL
test_order (__main__.TestExercice) ... ERROR

======================================================================
ERROR: test_order (__main__.TestExercice)
----------------------------------------------------------------------
Traceback (most recent call last):
  File "test_exercice.py", line 19, in test_order
    output = [exercice.order(v) for v in values]
  File "test_exercice.py", line 19, in <listcomp>
    output = [exercice.order(v) for v in values]
  File "/home/runner/work/c01_ch6_exercices-marianachng/c01_ch6_exercices-marianachng/exercice.py", line 9, in order
    values = [input("Entrez...") for _ in range(10)]
  File "/home/runner/work/c01_ch6_exercices-marianachng/c01_ch6_exercices-marianachng/exercice.py", line 9, in <listcomp>
    values = [input("Entrez...") for _ in range(10)]
EOFError: EOF when reading a line

======================================================================
FAIL: test_anagram (__main__.TestExercice)
----------------------------------------------------------------------
Traceback (most recent call last):
  File "test_exercice.py", line 40, in test_anagram
    'Erreur dans la vérification de l\'anagramme'
AssertionError: Lists differ: [True, True] != [True, False]

First differing element 1:
True
False

- [True, True]
+ [True, False] : Erreur dans la vérification de l'anagramme

======================================================================
FAIL: test_doubles (__main__.TestExercice)
----------------------------------------------------------------------
Traceback (most recent call last):
  File "test_exercice.py", line 55, in test_doubles
    'Erreur dans les doublons'
AssertionError: Lists differ: [True, False] != [False, True]

First differing element 0:
True
False

- [True, False]
+ [False, True] : Erreur dans les doublons

======================================================================
FAIL: test_grades (__main__.TestExercice)
----------------------------------------------------------------------
Traceback (most recent call last):
  File "test_exercice.py", line 69, in test_grades
    'Erreur dans les notes'
AssertionError: [('Sam', [100.0, 0.0])] is not an instance of <class 'dict'> : First argument is not a dictionary

======================================================================
FAIL: test_histogram (__main__.TestExercice)
----------------------------------------------------------------------
Traceback (most recent call last):
  File "test_exercice.py", line 84, in test_histogram
    'Erreur dans les histogrammes'
AssertionError: [({'B': 1, 'o': 4, 'n': 2, 'j': 2, 'u': 2, 'r': 2, ',': 1, ' ': 1, 'b': 1}, []), ({'J': 1, "'": 1, 'a': 6, 'd': 1, 'o': 4, 'r': 3, 'e': 7, ' ': 5, 'm': 2, 'n': 4, 'b': 1, 'c': 3, 'l': 3, 'u': 2, 't': 2, 'g': 2, 'i': 5, 'f': 1, 'q': 1, '/': 1}, ['a', 'e'])] is not an instance of <class 'dict'> : First argument is not a dictionary

----------------------------------------------------------------------
Ran 5 tests in 0.001s

FAILED (failures=4, errors=1)
